<?xml version="1.0" encoding="utf-8"?>
<!-- This URDF was automatically created by SolidWorks to URDF Exporter! Originally created by Stephen Brawner (brawner@gmail.com) 
     Commit Version: 1.6.0-4-g7f85cfe  Build Version: 1.6.7995.38578
     For more information, please see http://wiki.ros.org/sw_urdf_exporter -->
<robot
  name="four_skating">

  <!-- 底座 base_link -->
  <link name="base_link">
    <inertial>
      <origin
        xyz="-1.31284969742887E-17 -6.54836755974205E-18 0.005"
        rpy="0 0 0" />
      <mass
        value="0.0392146018366026" />
      <inertia
        ixx="8.24767242466039E-06"
        ixy="1.96455395481344E-21"
        ixz="1.97031431348917E-22"
        iyy="2.05319092153479E-05"
        iyz="3.32608016050597E-22"
        izz="2.81260049427316E-05" />
    </inertial>
    <visual>
      <origin
        xyz="0 0 0"
        rpy="0 0 0" />
      <geometry>
        <mesh
          filename="package://four_skating/meshes/base_link.STL" />
      </geometry>
      <material
        name="">
        <color
          rgba="1 1 1 1" />
      </material>
    </visual>
    <collision>
      <origin
        xyz="0 0 0"
        rpy="0 0 0" />
      <geometry>
        <mesh
          filename="package://four_skating/meshes/base_link.STL" />
      </geometry>
    </collision>
  </link>

<!-- ########## left_forward 左前轮 ########## -->
  <!-- 左前轮link1 left_forward_link_1-->
  <link name="left_forward_link_1">
    <inertial>
      <origin
        xyz="0 0.00469653105239854 0.00482901223692219"
        rpy="0 0 0" />
      <mass
        value="0.00155580902775302" />
      <inertia
        ixx="1.72003165569314E-07"
        ixy="8.27180612553028E-25"
        ixz="-8.89219158494505E-24"
        iyy="1.57424830559838E-07"
        iyz="7.11130751606718E-09"
        izz="3.08875512830852E-08" />
    </inertial>
    <visual>
      <origin
        xyz="0 0 0"
        rpy="0 0 0" />
      <geometry>
        <mesh
          filename="package://four_skating/meshes/left_forward_link_1.STL" />
      </geometry>
      <material
        name="">
        <color
          rgba="1 1 1 1" />
      </material>
    </visual>
    <collision>
      <origin
        xyz="0 0 0"
        rpy="0 0 0" />
      <geometry>
        <mesh
          filename="package://four_skating/meshes/left_forward_link_1.STL" />
      </geometry>
    </collision>
  </link>

  <!-- 左前轮joint1 left_forward_joint_1 -->
  <joint name="left_forward_joint_1" type="continuous">
    <origin
      xyz="0.0399999999999999 0.0250000000000002 0"
      rpy="1.5707963267949 0 3.02538154316369" />
    <parent
      link="base_link" />
    <child
      link="left_forward_link_1" />
    <axis
      xyz="0 0 1" />
  </joint>
  
  <!-- 左前轮link2 left_forward_link_2 -->
  <link name="left_forward_link_2">
    <inertial>
      <origin
        xyz="0 0.000951178470486614 -0.0156825282638125"
        rpy="0 0 0" />
      <mass
        value="0.000410674770424681" />
      <inertia
        ixx="3.37221691289327E-08"
        ixy="-2.58493941422821E-26"
        ixz="1.0352682353984E-23"
        iyy="3.40937232189665E-08"
        iyz="-1.40072591959393E-09"
        izz="1.23732540087662E-09" />
    </inertial>
    <visual>
      <origin
        xyz="0 0 0"
        rpy="0 0 0" />
      <geometry>
        <mesh
          filename="package://four_skating/meshes/left_forward_link_2.STL" />
      </geometry>
      <material
        name="">
        <color
          rgba="1 1 1 1" />
      </material>
    </visual>
    <collision>
      <origin
        xyz="0 0 0"
        rpy="0 0 0" />
      <geometry>
        <mesh
          filename="package://four_skating/meshes/left_forward_link_2.STL" />
      </geometry>
    </collision>
  </link>

  <!-- 左前轮joint2 left_forward_joint_2-->
  <joint name="left_forward_joint_2" type="prismatic">
    <origin
      xyz="0 0.005 0.019733"
      rpy="3.1416 0 3.1416" />
    <parent
      link="left_forward_link_1" />
    <child
      link="left_forward_link_2" />
    <axis
      xyz="0 0 1" />
    <limit
      lower="0"
      upper="0"
      effort="0"
      velocity="0" />
  </joint>

  <!-- 左前轮link left_forward_wheel-->
  <link name="left_forward_wheel_link">
    <inertial>
      <origin
        xyz="-2.15105711021124E-16 -1.52655665885959E-16 -0.00243277831827535"
        rpy="0 0 0" />
      <mass
        value="0.00235619449019234" />
      <inertia
        ixx="1.00629139685298E-07"
        ixy="-1.78877807464592E-23"
        ixz="4.21862112402044E-23"
        iyy="1.00629139685298E-07"
        iyz="3.84638984837158E-23"
        izz="1.91440802328128E-07" />
    </inertial>
    <visual>
      <origin
        xyz="0 0 0"
        rpy="0 0 0" />
      <geometry>
        <mesh
          filename="package://four_skating/meshes/left_forward_wheel_link.STL" />
      </geometry>
      <material
        name="">
        <color
          rgba="1 1 1 1" />
      </material>
    </visual>
    <collision>
      <origin
        xyz="0 0 0"
        rpy="0 0 0" />
      <geometry>
        <mesh
          filename="package://four_skating/meshes/left_forward_wheel_link.STL" />
      </geometry>
    </collision>
  </link>

  <!-- 左前轮joint left_forward_wheel_joint-->
  <joint name="left_forward_wheel_joint" type="continuous">
    <origin
      xyz="0 0 -0.0246638915913767"
      rpy="0 0 2.54006675826632" />
    <parent
      link="left_forward_link_2" />
    <child
      link="left_forward_wheel_link" />
    <axis
      xyz="0 0 1" />
  </joint>


<!-- ########## right_forward 右前轮 ########## -->
  <!-- 右前轮link1 right_forward_link_1-->
  <link name="right_forward_link_1">
    <inertial>
      <origin
        xyz="-3.46944695195361E-18 0.00469653105239854 0.00482901223692221"
        rpy="0 0 0" />
      <mass
        value="0.00155580902775302" />
      <inertia
        ixx="1.72003165569314E-07"
        ixy="-4.13590306276514E-24"
        ixz="-1.57164316385075E-23"
        iyy="1.57424830559838E-07"
        iyz="7.11130751606718E-09"
        izz="3.08875512830852E-08" />
    </inertial>
    <visual>
      <origin
        xyz="0 0 0"
        rpy="0 0 0" />
      <geometry>
        <mesh
          filename="package://four_skating/meshes/right_forward_link_1.STL" />
      </geometry>
      <material
        name="">
        <color
          rgba="1 1 1 1" />
      </material>
    </visual>
    <collision>
      <origin
        xyz="0 0 0"
        rpy="0 0 0" />
      <geometry>
        <mesh
          filename="package://four_skating/meshes/right_forward_link_1.STL" />
      </geometry>
    </collision>
  </link>

  <!-- 右前轮joint1 ight_forward_joint_1-->
  <joint name="right_forward_joint_1" type="continuous">
    <origin
      xyz="0.04 -0.025 0"
      rpy="1.5708 0 0.50352" />
    <parent
      link="base_link" />
    <child
      link="right_forward_link_1" />
    <axis
      xyz="0 0 1" />
  </joint>

  <!-- 右前轮link2 right_forward_link_2-->
  <link name="right_forward_link_2">
    <inertial>
      <origin
        xyz="1.04083408558608E-17 0.00095117847048663 -0.0181989952794125"
        rpy="0 0 0" />
      <mass
        value="0.000410674770424681" />
      <inertia
        ixx="3.37221691289327E-08"
        ixy="-1.03996423877919E-25"
        ixz="5.16987882845642E-25"
        iyy="3.40937232189665E-08"
        iyz="-1.40072591959389E-09"
        izz="1.23732540087662E-09" />
    </inertial>
    <visual>
      <origin
        xyz="0 0 0"
        rpy="0 0 0" />
      <geometry>
        <mesh
          filename="package://four_skating/meshes/right_forward_link_2.STL" />
      </geometry>
      <material
        name="">
        <color
          rgba="1 1 1 1" />
      </material>
    </visual>
    <collision>
      <origin
        xyz="0 0 0"
        rpy="0 0 0" />
      <geometry>
        <mesh
          filename="package://four_skating/meshes/right_forward_link_2.STL" />
      </geometry>
    </collision>
  </link>

  <!-- 右前轮joint2 right_forward_joint_2-->
  <joint name="right_forward_joint_2" type="prismatic">
    <origin
      xyz="0 0.005 0.00583598115499422"
      rpy="-3.14159265358979 0 3.14159265358979" />
    <parent
      link="right_forward_link_1" />
    <child
      link="right_forward_link_2" />
    <axis
      xyz="0 0 1" />
    <limit
      lower="0"
      upper="0"
      effort="0"
      velocity="0" />
  </joint>

  <!-- 右前轮link right_forward_wheel_link-->
  <link name="right_forward_wheel_link">
    <inertial>
      <origin
        xyz="5.20417042793042E-18 1.73472347597681E-17 -0.0164181508625821"
        rpy="0 0 0" />
      <mass
        value="0.00235619449019235" />
      <inertia
        ixx="1.00629139685298E-07"
        ixy="-3.30872245021211E-24"
        ixz="0"
        iyy="1.00629139685298E-07"
        iyz="9.92616735063633E-24"
        izz="1.91440802328128E-07" />
    </inertial>
    <visual>
      <origin
        xyz="0 0 0"
        rpy="0 0 0" />
      <geometry>
        <mesh
          filename="package://four_skating/meshes/right_forward_wheel_link.STL" />
      </geometry>
      <material
        name="">
        <color
          rgba="1 1 1 1" />
      </material>
    </visual>
    <collision>
      <origin
        xyz="0 0 0"
        rpy="0 0 0" />
      <geometry>
        <mesh
          filename="package://four_skating/meshes/right_forward_wheel_link.STL" />
      </geometry>
    </collision>
  </link>

  <!-- 右前轮joint right_forward_wheel_joint-->
  <joint name="right_forward_wheel_joint" type="continuous">
    <origin
      xyz="0 0 -0.0131949860626701"
      rpy="0 0 -1.15776168458666" />
    <parent
      link="right_forward_link_2" />
    <child
      link="right_forward_wheel_link" />
    <axis
      xyz="0 0 1" />
  </joint>
  
<!-- ########## left_backward 左后轮 ########## -->
  <!-- 左后轮link1 left_backward_link_1-->
  <link name="left_backward_link_1">
    <inertial>
      <origin
        xyz="0 0.00469653105239854 0.0048290122369222"
        rpy="0 0 0" />
      <mass
        value="0.00155580902775302" />
      <inertia
        ixx="1.72003165569314E-07"
        ixy="-2.8951321439356E-24"
        ixz="3.14328632770151E-23"
        iyy="1.57424830559838E-07"
        iyz="7.11130751606719E-09"
        izz="3.08875512830852E-08" />
    </inertial>
    <visual>
      <origin
        xyz="0 0 0"
        rpy="0 0 0" />
      <geometry>
        <mesh
          filename="package://four_skating/meshes/left_backward_link_1.STL" />
      </geometry>
      <material
        name="">
        <color
          rgba="1 1 1 1" />
      </material>
    </visual>
    <collision>
      <origin
        xyz="0 0 0"
        rpy="0 0 0" />
      <geometry>
        <mesh
          filename="package://four_skating/meshes/left_backward_link_1.STL" />
      </geometry>
    </collision>
  </link>

  <!-- 左后轮joint1 right_backward_joint_1-->
  <joint name="left_backward_joint_1" type="continuous">
    <origin
      xyz="-0.04 0.025 0"
      rpy="1.5708 0 -2.7407" />
    <parent
      link="base_link" />
    <child
      link="left_backward_link_1" />
    <axis
      xyz="0 0 1" />
  </joint>

  <!-- 左后轮link2 left_backward_link_2-->
  <link name="left_backward_link_2">
    <inertial>
      <origin
        xyz="-3.46944695195361E-18 0.000951178470486647 -0.0178825156824723"
        rpy="0 0 0" />
      <mass
        value="0.000410674770424681" />
      <inertia
        ixx="3.37221691289326E-08"
        ixy="-1.24077091882954E-24"
        ixz="-9.35748067950613E-24"
        iyy="3.40937232189665E-08"
        iyz="-1.40072591959386E-09"
        izz="1.23732540087661E-09" />
    </inertial>
    <visual>
      <origin
        xyz="0 0 0"
        rpy="0 0 0" />
      <geometry>
        <mesh
          filename="package://four_skating/meshes/left_backward_link_2.STL" />
      </geometry>
      <material
        name="">
        <color
          rgba="1 1 1 1" />
      </material>
    </visual>
    <collision>
      <origin
        xyz="0 0 0"
        rpy="0 0 0" />
      <geometry>
        <mesh
          filename="package://four_skating/meshes/left_backward_link_2.STL" />
      </geometry>
    </collision>
  </link>

  <!-- 左后轮joint2 left_backward_joint_2-->
  <joint name="left_backward_joint_2" type="prismatic">
    <origin
      xyz="0 0.005 0.00812196270704283"
      rpy="3.14159265358979 0 3.14159265358979" />
    <parent
      link="left_backward_link_1" />
    <child
      link="left_backward_link_2" />
    <axis
      xyz="0 0 1" />
    <limit
      lower="0"
      upper="0"
      effort="0"
      velocity="0" />
  </joint>
  
  <!-- 左后轮link left_backward_wheel_link-->
  <link name="left_backward_wheel_link">
    <inertial>
      <origin
        xyz="7.63278329429795E-17 1.82145964977565E-17 -0.0131328631479988"
        rpy="0 0 0" />
      <mass
        value="0.00235619449019234" />
      <inertia
        ixx="1.00629139685298E-07"
        ixy="-5.16987882845642E-24"
        ixz="9.92616735063633E-24"
        iyy="1.00629139685298E-07"
        iyz="-2.39882377640378E-23"
        izz="1.91440802328128E-07" />
    </inertial>
    <visual>
      <origin
        xyz="0 0 0"
        rpy="0 0 0" />
      <geometry>
        <mesh
          filename="package://four_skating/meshes/left_backward_wheel_link.STL" />
      </geometry>
      <material
        name="">
        <color
          rgba="1 1 1 1" />
      </material>
    </visual>
    <collision>
      <origin
        xyz="0 0 0"
        rpy="0 0 0" />
      <geometry>
        <mesh
          filename="package://four_skating/meshes/left_backward_wheel_link.STL" />
      </geometry>
    </collision>
  </link>
  
  <!-- 左后轮joint left_backward_wheel_joint-->
  <joint name="left_backward_wheel_joint" type="continuous">
    <origin
      xyz="0 0 -0.0161637941803131"
      rpy="0 0 -0.206289656954149" />
    <parent
      link="left_backward_link_2" />
    <child
      link="left_backward_wheel_link" />
    <axis
      xyz="0 0 1" />
  </joint>


<!-- ########## right_backward 右后轮 ########## -->
  <!-- 右后轮link1 right_backward_link_1-->
  <link name="right_backward_link_1">
    <inertial>
      <origin
        xyz="6.93889390390723E-18 0.00469653105239854 0.00482901223692219"
        rpy="0 0 0" />
      <mass
        value="0.00155580902775302" />
      <inertia
        ixx="1.72003165569314E-07"
        ixy="3.30872245021211E-24"
        ixz="3.30872245021211E-23"
        iyy="1.57424830559838E-07"
        iyz="7.11130751606718E-09"
        izz="3.08875512830852E-08" />
    </inertial>
    <visual>
      <origin
        xyz="0 0 0"
        rpy="0 0 0" />
      <geometry>
        <mesh
          filename="package://four_skating/meshes/right_backward_link_1.STL" />
      </geometry>
      <material
        name="">
        <color
          rgba="1 1 1 1" />
      </material>
    </visual>
    <collision>
      <origin
        xyz="0 0 0"
        rpy="0 0 0" />
      <geometry>
        <mesh
          filename="package://four_skating/meshes/right_backward_link_1.STL" />
      </geometry>
    </collision>
  </link>

  <!-- 右后轮joint1 right_backward_joint_1-->
  <joint name="right_backward_joint_1" type="continuous">
    <origin
      xyz="-0.04 -0.025 0"
      rpy="1.5707963267949 0 -0.264786446467445" />
    <parent
      link="base_link" />
    <child
      link="right_backward_link_1" />
    <axis
      xyz="0 0 1" />
  </joint>

  <!-- 右后轮link2 right_backward_link_2-->
  <link name="right_backward_link_2">
    <inertial>
      <origin
        xyz="1.38777878078145E-17 0.000951178470486639 -0.0140312019842561"
        rpy="0 0 0" />
      <mass
        value="0.000410674770424681" />
      <inertia
        ixx="3.37221691289327E-08"
        ixy="-9.49742628874355E-26"
        ixz="8.11670976067658E-24"
        iyy="3.40937232189666E-08"
        iyz="-1.40072591959388E-09"
        izz="1.23732540087662E-09" />
    </inertial>
    <visual>
      <origin
        xyz="0 0 0"
        rpy="0 0 0" />
      <geometry>
        <mesh
          filename="package://four_skating/meshes/right_backward_link_2.STL" />
      </geometry>
      <material
        name="">
        <color
          rgba="1 1 1 1" />
      </material>
    </visual>
    <collision>
      <origin
        xyz="0 0 0"
        rpy="0 0 0" />
      <geometry>
        <mesh
          filename="package://four_skating/meshes/right_backward_link_2.STL" />
      </geometry>
    </collision>
  </link>

  <!-- 右后轮joint2 right_backward_joint_2-->
  <joint name="right_backward_joint_2" type="prismatic">
    <origin
      xyz="0 0.00500000000000001 0.0181150724675244"
      rpy="-3.14159265358979 0 3.14159265358979" />
    <parent
      link="right_backward_link_1" />
    <child
      link="right_backward_link_2" />
    <axis
      xyz="0 0 1" />
    <limit
      lower="0"
      upper="0"
      effort="0"
      velocity="0" />
  </joint>

  <!-- 右后轮link right_backward_wheel_link-->
  <link name="right_backward_wheel_link">
    <inertial>
      <origin
        xyz="0 -3.46944695195361E-18 -0.00215755727168261"
        rpy="0 0 0" />
      <mass
        value="0.00235619449019235" />
      <inertia
        ixx="1.00629139685298E-07"
        ixy="-2.00591298544109E-23"
        ixz="8.27180612553028E-24"
        iyy="1.00629139685298E-07"
        iyz="4.13590306276514E-23"
        izz="1.91440802328128E-07" />
    </inertial>
    <visual>
      <origin
        xyz="0 0 0"
        rpy="0 0 0" />
      <geometry>
        <mesh
          filename="package://four_skating/meshes/right_backward_wheel_link.STL" />
      </geometry>
      <material
        name="">
        <color
          rgba="1 1 1 1" />
      </material>
    </visual>
    <collision>
      <origin
        xyz="0 0 0"
        rpy="0 0 0" />
      <geometry>
        <mesh
          filename="package://four_skating/meshes/right_backward_wheel_link.STL" />
      </geometry>
    </collision>
  </link>

  <!-- 右后轮joint right_backward_wheel_joint-->
  <joint name="right_backward_wheel_joint"
    type="continuous">
    <origin
      xyz="0 0 -0.0232877863584131"
      rpy="0 0 -0.377256984560737" />
    <parent
      link="right_backward_link_2" />
    <child
      link="right_backward_wheel_link" />
    <axis
      xyz="0 0 1" />
  </joint>
</robot>
